Workbook
Name SlicerCache_Table_1_Col_3: #N/A
Name SlicerCache_Table_1_Col_4: #N/A

Sheet sales_pipeline
A1: opportunity_id | B1: sales_agent | C1: manager | D1: regional_office | E1: product | F1: account | G1: account_sector | H1: size | I1: location | J1: deal_stage | K1: engage_date | L1: close_date | M1: close_value
A2: 1C1I7A6R | B2: Moses Frase | C2: {=_xlfn.XLOOKUP($B2, sales_teams!$A$2:$A$36, sales_teams!$B$2:$B$36)} -> Dustin Brinkmann | D2: {=_xlfn.XLOOKUP($B2, sales_teams!$A$2:$A$36, sales_teams!$C$2:$C$36)} -> Central | E2: GTX Plus Basic | F2: Cancity | G2: {=IF($F2="", "", _xlfn.XLOOKUP($F2,accounts!$A$2:$A$86,accounts!$B$2:$B$86, "Other"))} -> retail | H2: {=IF($F2="", "", IFS(_xlfn.XLOOKUP($F2, accounts!$A$2:$A$86, accounts!$E$2:$E$86, 0)>=1000, "Enterprise", _xlfn.XLOOKUP($F2, accounts!$A$2:$A$86, accounts!$E$2:$E$86, 0)>=100, "Mid-Market", TRUE, "SMB"))} -> Enterprise | I2: {=IF($F2="", "", _xlfn.XLOOKUP($F2,accounts!$A$2:$A$86,accounts!$F$2:$F$86, "Other"))} -> United States | J2: Won | K2: 42663 | L2: 42795 | M2: 1054
A3: Z063OYW0 | B3: Darcel Schlecht | C3: {=_xlfn.XLOOKUP($B3, sales_teams!$A$2:$A$36, sales_teams!$B$2:$B$36)} -> Melvin Marxen | D3: {=_xlfn.XLOOKUP($B3, sales_teams!$A$2:$A$36, sales_teams!$C$2:$C$36)} -> Central | E3: GTXPro | F3: Isdom | G3: {=IF($F3="", "", _xlfn.XLOOKUP($F3,accounts!$A$2:$A$86,accounts!$B$2:$B$86, "Other"))} -> medical | H3: {=IF($F3="", "", IFS(_xlfn.XLOOKUP($F3, accounts!$A$2:$A$86, accounts!$E$2:$E$86, 0)>=1000, "Enterprise", _xlfn.XLOOKUP($F3, accounts!$A$2:$A$86, accounts!$E$2:$E$86, 0)>=100, "Mid-Market", TRUE, "SMB"))} -> Enterprise | I3: {=IF($F3="", "", _xlfn.XLOOKUP($F3,accounts!$A$2:$A$86,accounts!$F$2:$F$86, "Other"))} -> United States | J3: Won | K3: 42668 | L3: 42805 | M3: 4514
A4: EC4QE1BX | B4: Darcel Schlecht | C4: {=_xlfn.XLOOKUP($B4, sales_teams!$A$2:$A$36, sales_teams!$B$2:$B$36)} -> Melvin Marxen | D4: {=_xlfn.XLOOKUP($B4, sales_teams!$A$2:$A$36, sales_teams!$C$2:$C$36)} -> Central | E4: MG Special | F4: Cancity | G4: {=IF($F4="", "", _xlfn.XLOOKUP($F4,accounts!$A$2:$A$86,accounts!$B$2:$B$86, "Other"))} -> retail | H4: {=IF($F4="", "", IFS(_xlfn.XLOOKUP($F4, accounts!$A$2:$A$86, accounts!$E$2:$E$86, 0)>=1000, "Enterprise", _xlfn.XLOOKUP($F4, accounts!$A$2:$A$86, accounts!$E$2:$E$86, 0)>=100, "Mid-Market", TRUE, "SMB"))} -> Enterprise | I4: {=IF($F4="", "", _xlfn.XLOOKUP($F4,accounts!$A$2:$A$86,accounts!$F$2:$F$86, "Other"))} -> United States | J4: Won | K4: 42668 | L4: 42801 | M4: 50
A5: MV1LWRNH | B5: Moses Frase | C5: {=_xlfn.XLOOKUP($B5, sales_teams!$A$2:$A$36, sales_teams!$B$2:$B$36)} -> Dustin Brinkmann | D5: {=_xlfn.XLOOKUP($B5, sales_teams!$A$2:$A$36, sales_teams!$C$2:$C$36)} -> Central | E5: GTX Basic | F5: Codehow | G5: {=IF($F5="", "", _xlfn.XLOOKUP($F5,accounts!$A$2:$A$86,accounts!$B$2:$B$86, "Other"))} -> software | H5: {=IF($F5="", "", IFS(_xlfn.XLOOKUP($F5, accounts!$A$2:$A$86, accounts!$E$2:$E$86, 0)>=1000, "Enterprise", _xlfn.XLOOKUP($F5, accounts!$A$2:$A$86, accounts!$E$2:$E$86, 0)>=100, "Mid-Market", TRUE, "SMB"))} -> Enterprise | I5: {=IF($F5="", "", _xlfn.XLOOKUP($F5,accounts!$A$2:$A$86,accounts!$F$2:$F$86, "Other"))} -> United States | J5: Won | K5: 42668 | L5: 42803 | M5: 588
A6: PE84CX4O | B6: Zane Levy | C6: {=_xlfn.XLOOKUP($B6, sales_teams!$A$2:$A$36, sales_teams!$B$2:$B$36)} -> Summer Sewald | D6: {=_xlfn.XLOOKUP($B6, sales_teams!$A$2:$A$36, sales_teams!$C$2:$C$36)} -> West | E6: GTX Basic | F6: Hatfan | G6: {=IF($F6="", "", _xlfn.XLOOKUP($F6,accounts!$A$2:$A$86,accounts!$B$2:$B$86, "Other"))} -> services | H6: {=IF($F6="", "", IFS(_xlfn.XLOOKUP($F6, accounts!$A$2:$A$86, accounts!$E$2:$E$86, 0)>=1000, "Enterprise", _xlfn.XLOOKUP($F6, accounts!$A$2:$A$86, accounts!$E$2:$E$86, 0)>=100, "Mid-Market", TRUE, "SMB"))} -> Enterprise | I6: {=IF($F6="", "", _xlfn.XLOOKUP($F6,accounts!$A$2:$A$86,accounts!$F$2:$F$86, "Other"))} -> United States | J6: Won | K6: 42668 | L6: 42796 | M6: 517
A7: ZNBS69V1 | B7: Anna Snelling | C7: {=_xlfn.XLOOKUP($B7, sales_teams!$A$2:$A$36, sales_teams!$B$2:$B$36)} -> Dustin Brinkmann | D7: {=_xlfn.XLOOKUP($B7, sales_teams!$A$2:$A$36, sales_teams!$C$2:$C$36)} -> Central | E7: MG Special | F7: Ron-tech | G7: {=IF($F7="", "", _xlfn.XLOOKUP($F7,accounts!$A$2:$A$86,accounts!$B$2:$B$86, "Other"))} -> medical | H7: {=IF($F7="", "", IFS(_xlfn.XLOOKUP($F7, accounts!$A$2:$A$86, accounts!$E$2:$E$86, 0)>=1000, "Enterprise", _xlfn.XLOOKUP($F7, accounts!$A$2:$A$86, accounts!$E$2:$E$86, 0)>=100, "Mid-Market", TRUE, "SMB"))} -> Enterprise | I7: {=IF($F7="", "", _xlfn.XLOOKUP($F7,accounts!$A$2:$A$86,accounts!$F$2:$F$86, "Other"))} -> United States | J7: Won | K7: 42672 | L7: 42795 | M7: 49
A8: 9ME3374G | B8: Vicki Laflamme | C8: {=_xlfn.XLOOKUP($B8, sales_teams!$A$2:$A$36, sales_teams!$B$2:$B$36)} -> Celia Rouche | D8: {=_xlfn.XLOOKUP($B8, sales_teams!$A$2:$A$36, sales_teams!$C$2:$C$36)} -> West | E8: MG Special | F8: J-Texon | G8: {=IF($F8="", "", _xlfn.XLOOKUP($F8,accounts!$A$2:$A$86,accounts!$B$2:$B$86, "Other"))} -> retail | H8: {=IF($F8="", "", IFS(_xlfn.XLOOKUP($F8, accounts!$A$2:$A$86, accounts!$E$2:$E$86, 0)>=1000, "Enterprise", _xlfn.XLOOKUP($F8, accounts!$A$2:$A$86, accounts!$E$2:$E$86, 0)>=100, "Mid-Market", TRUE, "SMB"))} -> Enterprise | I8: {=IF($F8="", "", _xlfn.XLOOKUP($F8,accounts!$A$2:$A$86,accounts!$F$2:$F$86, "Other"))} -> United States | J8: Won | K8: 42673 | L8: 42796 | M8: 57
A9: 7GN8Q4LL | B9: Markita Hansen | C9: {=_xlfn.XLOOKUP($B9, sales_teams!$A$2:$A$36, sales_teams!$B$2:$B$36)} -> Celia Rouche | D9: {=_xlfn.XLOOKUP($B9, sales_teams!$A$2:$A$36, sales_teams!$C$2:$C$36)} -> West | E9: GTX Basic | F9: Cheers | G9: {=IF($F9="", "", _xlfn.XLOOKUP($F9,accounts!$A$2:$A$86,accounts!$B$2:$B$86, "Other"))} -> entertainment | H9: {=IF($F9="", "", IFS(_xlfn.XLOOKUP($F9, accounts!$A$2:$A$86, accounts!$E$2:$E$86, 0)>=1000, "Enterprise", _xlfn.XLOOKUP($F9, accounts!$A$2:$A$86, accounts!$E$2:$E$86, 0)>=100, "Mid-Market", TRUE, "SMB"))} -> Enterprise | I9: {=IF($F9="", "", _xlfn.XLOOKUP($F9,accounts!$A$2:$A$86,accounts!$F$2:$F$86, "Other"))} -> United States | J9: Won | K9: 42675 | L9: 42801 | M9: 601
A10: OLK9LKZB | B10: Niesha Huffines | C10: {=_xlfn.XLOOKUP($B10, sales_teams!$A$2:$A$36, sales_teams!$B$2:$B$36)} -> Melvin Marxen | D10: {=_xlfn.XLOOKUP($B10, sales_teams!$A$2:$A$36, sales_teams!$C$2:$C$36)} -> Central | E10: GTX Plus Basic | F10: Zumgoity | G10: {=IF($F10="", "", _xlfn.XLOOKUP($F10,accounts!$A$2:$A$86,accounts!$B$2:$B$86, "Other"))} -> medical | H10: {=IF($F10="", "", IFS(_xlfn.XLOOKUP($F10, accounts!$A$2:$A$86, accounts!$E$2:$E$86, 0)>=1000, "Enterprise", _xlfn.XLOOKUP($F10, accounts!$A$2:$A$86, accounts!$E$2:$E$86, 0)>=100, "Mid-Market", TRUE, "SMB"))} -> Enterprise | I10: {=IF($F10="", "", _xlfn.XLOOKUP($F10,accounts!$A$2:$A$86,accounts!$F$2:$F$86, "Other"))} -> United States | J10: Won | K10: 42675 | L10: 42797 | M10: 1026
A11: HAXMC4IX | B11: James Ascencio | C11: {=_xlfn.XLOOKUP($B11, sales_teams!$A$2:$A$36, sales_teams!$B$2:$B$36)} -> Summer Sewald | D11: {=_xlfn.XLOOKUP($B11, sales_teams!$A$2:$A$36, sales_teams!$C$2:$C$36)} -> West | E11: MG Advanced | G11: {=IF($F11="", "", _xlfn.XLOOKUP($F11,accounts!$A$2:$A$86,accounts!$B$2:$B$86, "Other"))} | H11: {=IF($F11="", "", IFS(_xlfn.XLOOKUP($F11, accounts!$A$2:$A$86, accounts!$E$2:$E$86, 0)>=1000, "Enterprise", _xlfn.XLOOKUP($F11, accounts!$A$2:$A$86, accounts!$E$2:$E$86, 0)>=100, "Mid-Market", TRUE, "SMB"))} | I11: {=IF($F11="", "", _xlfn.XLOOKUP($F11,accounts!$A$2:$A$86,accounts!$F$2:$F$86, "Other"))} | J11: Engaging | K11: 42677
A12: NL3JZH1Z | B12: Anna Snelling | C12: {=_xlfn.XLOOKUP($B12, sales_teams!$A$2:$A$36, sales_teams!$B$2:$B$36)} -> Dustin Brinkmann | D12: {=_xlfn.XLOOKUP($B12, sales_teams!$A$2:$A$36, sales_teams!$C$2:$C$36)} -> Central | E12: MG Special | F12: Bioholding | G12: {=IF($F12="", "", _xlfn.XLOOKUP($F12,accounts!$A$2:$A$86,accounts!$B$2:$B$86, "Other"))} -> medical | H12: {=IF($F12="", "", IFS(_xlfn.XLOOKUP($F12, accounts!$A$2:$A$86, accounts!$E$2:$E$86, 0)>=1000, "Enterprise", _xlfn.XLOOKUP($F12, accounts!$A$2:$A$86, accounts!$E$2:$E$86, 0)>=100, "Mid-Market", TRUE, "SMB"))} -> Enterprise | I12: {=IF($F12="", "", _xlfn.XLOOKUP($F12,accounts!$A$2:$A$86,accounts!$F$2:$F$86, "Other"))} -> Philipines | J12: Won | K12: 42678 | L12: 42804 | M12: 53
A13: KWVA7VR1 | B13: Gladys Colclough | C13: {=_xlfn.XLOOKUP($B13, sales_teams!$A$2:$A$36, sales_teams!$B$2:$B$36)} -> Melvin Marxen | D13: {=_xlfn.XLOOKUP($B13, sales_teams!$A$2:$A$36, sales_teams!$C$2:$C$36)} -> Central | E13: GTXPro | F13: Genco Pura Olive Oil Company | G13: {=IF($F13="", "", _xlfn.XLOOKUP($F13,accounts!$A$2:$A$86,accounts!$B$2:$B$86, "Other"))} -> retail | H13: {=IF($F13="", "", IFS(_xlfn.XLOOKUP($F13, accounts!$A$2:$A$86, accounts!$E$2:$E$86, 0)>=1000, "Enterprise", _xlfn.XLOOKUP($F13, accounts!$A$2:$A$86, accounts!$E$2:$E$86, 0)>=100, "Mid-Market", TRUE, "SMB"))} -> Enterprise | I13: {=IF($F13="", "", _xlfn.XLOOKUP($F13,accounts!$A$2:$A$86,accounts!$F$2:$F$86, "Other"))} -> Italy | J13: Lost | K13: 42678 | L13: 42812 | M13: 0
A14: S8DX3XOU | B14: James Ascencio | C14: {=_xlfn.XLOOKUP($B14, sales_teams!$A$2:$A$36, sales_teams!$B$2:$B$36)} -> Summer Sewald | D14: {=_xlfn.XLOOKUP($B14, sales_teams!$A$2:$A$36, sales_teams!$C$2:$C$36)} -> West | E14: GTX Plus Pro | F14: Sunnamplex | G14: {=IF($F14="", "", _xlfn.XLOOKUP($F14,accounts!$A$2:$A$86,accounts!$B$2:$B$86, "Other"))} -> marketing | H14: {=IF($F14="", "", IFS(_xlfn.XLOOKUP($F14, accounts!$A$2:$A$86, accounts!$E$2:$E$86, 0)>=1000, "Enterprise", _xlfn.XLOOKUP($F14, accounts!$A$2:$A$86, accounts!$E$2:$E$86, 0)>=100, "Mid-Market", TRUE, "SMB"))} -> Enterprise | I14: {=IF($F14="", "", _xlfn.XLOOKUP($F14,accounts!$A$2:$A$86,accounts!$F$2:$F$86, "Other"))} -> Poland | J14: Won | K14: 42678 | L14: 42804 | M14: 5169
A15: ENB2XD8G | B15: Maureen Marcano | C15: {=_xlfn.XLOOKUP($B15, sales_teams!$A$2:$A$36, sales_teams!$B$2:$B$36)} -> Summer Sewald | D15: {=_xlfn.XLOOKUP($B15, sales_teams!$A$2:$A$36, sales_teams!$C$2:$C$36)} -> West | E15: GTX Plus Pro | F15: Sonron | G15: {=IF($F15="", "", _xlfn.XLOOKUP($F15,accounts!$A$2:$A$86,accounts!$B$2:$B$86, "Other"))} -> telecommunications | H15: {=IF($F15="", "", IFS(_xlfn.XLOOKUP($F15, accounts!$A$2:$A$86, accounts!$E$2:$E$86, 0)>=1000, "Enterprise", _xlfn.XLOOKUP($F15, accounts!$A$2:$A$86, accounts!$E$2:$E$86, 0)>=100, "Mid-Market", TRUE, "SMB"))} -> Enterprise | I15: {=IF($F15="", "", _xlfn.XLOOKUP($F15,accounts!$A$2:$A$86,accounts!$F$2:$F$86, "Other"))} -> United States | J15: Won | K15: 42678 | L15: 42800 | M15: 4631
A16: 09YE9QOV | B16: Hayden Neloms | C16: {=_xlfn.XLOOKUP($B16, sales_teams!$A$2:$A$36, sales_teams!$B$2:$B$36)} -> Celia Rouche | D16: {=_xlfn.XLOOKUP($B16, sales_teams!$A$2:$A$36, sales_teams!$C$2:$C$36)} -> West | E16: MG Advanced | F16: Finjob | G16: {=IF($F16="", "", _xlfn.XLOOKUP($F16,accounts!$A$2:$A$86,accounts!$B$2:$B$86, "Other"))} -> employment | H16: {=IF($F16="", "", IFS(_xlfn.XLOOKUP($F16, accounts!$A$2:$A$86, accounts!$E$2:$E$86, 0)>=1000, "Enterprise", _xlfn.XLOOKUP($F16, accounts!$A$2:$A$86, accounts!$E$2:$E$86, 0)>=100, "Mid-Market", TRUE, "SMB"))} -> Enterprise | I16: {=IF($F16="", "", _xlfn.XLOOKUP($F16,accounts!$A$2:$A$86,accounts!$F$2:$F$86, "Other"))} -> United States | J16: Won | K16: 42679 | L16: 42805 | M16: 3393
A17: 3F5MZNEH | B17: Rosalina Dieter | C17: {=_xlfn.XLOOKUP($B17, sales_teams!$A$2:$A$36, sales_teams!$B$2:$B$36)} -> Celia Rouche | D17: {=_xlfn.XLOOKUP($B17, sales_teams!$A$2:$A$36, sales_teams!$C$2:$C$36)} -> West | E17: MG Special | F17: Sonron | G17: {=IF($F17="", "", _xlfn.XLOOKUP($F17,accounts!$A$2:$A$86,accounts!$B$2:$B$86, "Other"))} -> telecommunications | H17: {=IF($F17="", "", IFS(_xlfn.XLOOKUP($F17, accounts!$A$2:$A$86, accounts!$E$2:$E$86, 0)>=1000, "Enterprise", _xlfn.XLOOKUP($F17, accounts!$A$2:$A$86, accounts!$E$2:$E$86, 0)>=100, "Mid-Market", TRUE, "SMB"))} -> Enterprise | I17: {=IF($F17="", "", _xlfn.XLOOKUP($F17,accounts!$A$2:$A$86,accounts!$F$2:$F$86, "Other"))} -> United States | J17: Lost | K17: 42679 | L17: 42797 | M17: 0
A18: M6WEJXC0 | B18: Rosalina Dieter | C18: {=_xlfn.XLOOKUP($B18, sales_teams!$A$2:$A$36, sales_teams!$B$2:$B$36)} -> Celia Rouche | D18: {=_xlfn.XLOOKUP($B18, sales_teams!$A$2:$A$36, sales_teams!$C$2:$C$36)} -> West | E18: MG Advanced | F18: Scotfind | G18: {=IF($F18="", "", _xlfn.XLOOKUP($F18,accounts!$A$2:$A$86,accounts!$B$2:$B$86, "Other"))} -> software | H18: {=IF($F18="", "", IFS(_xlfn.XLOOKUP($F18, accounts!$A$2:$A$86, accounts!$E$2:$E$86, 0)>=1000, "Enterprise", _xlfn.XLOOKUP($F18, accounts!$A$2:$A$86, accounts!$E$2:$E$86, 0)>=100, "Mid-Market", TRUE, "SMB"))} -> Enterprise | I18: {=IF($F18="", "", _xlfn.XLOOKUP($F18,accounts!$A$2:$A$86,accounts!$F$2:$F$86, "Other"))} -> United States | J18: Won | K18: 42679 | L18: 42800 | M18: 3284
A19: 6PTR7VBR | B19: Versie Hillebrand | C19: {=_xlfn.XLOOKUP($B19, sales_teams!$A$2:$A$36, sales_teams!$B$2:$B$36)} -> Dustin Brinkmann | D19: {=_xlfn.XLOOKUP($B19, sales_teams!$A$2:$A$36, sales_teams!$C$2:$C$36)} -> Central | E19: MG Special | F19: Treequote | G19: {=IF($F19="", "", _xlfn.XLOOKUP($F19,accounts!$A$2:$A$86,accounts!$B$2:$B$86, "Other"))} -> telecommunications | H19: {=IF($F19="", "", IFS(_xlfn.XLOOKUP($F19, accounts!$A$2:$A$86, accounts!$E$2:$E$86, 0)>=1000, "Enterprise", _xlfn.XLOOKUP($F19, accounts!$A$2:$A$86, accounts!$E$2:$E$86, 0)>=100, "Mid-Market", TRUE, "SMB"))} -> Enterprise | I19: {=IF($F19="", "", _xlfn.XLOOKUP($F19,accounts!$A$2:$A$86,accounts!$F$2:$F$86, "Other"))} -> United States | J19: Won | K19: 42680 | L19: 42799 | M19: 61
A20: 902REDPA | B20: Daniell Hammack | C20: {=_xlfn.XLOOKUP($B20, sales_teams!$A$2:$A$36, sales_teams!$B$2:$B$36)} -> Rocco Neubert | D20: {=_xlfn.XLOOKUP($B20, sales_teams!$A$2:$A$36, sales_teams!$C$2:$C$36)} -> East | E20: GTXPro | F20: Xx-zobam | G20: {=IF($F20="", "", _xlfn.XLOOKUP($F20,accounts!$A$2:$A$86,accounts!$B$2:$B$86, "Other"))} -> entertainment | H20: {=IF($F20="", "", IFS(_xlfn.XLOOKUP($F20, accounts!$A$2:$A$86, accounts!$E$2:$E$86, 0)>=1000, "Enterprise", _xlfn.XLOOKUP($F20, accounts!$A$2:$A$86, accounts!$E$2:$E$86, 0)>=100, "Mid-Market", TRUE, "SMB"))} -> Enterprise | I20: {=IF($F20="", "", _xlfn.XLOOKUP($F20,accounts!$A$2:$A$86,accounts!$F$2:$F$86, "Other"))} -> United States | J20: Lost | K20: 42681 | L20: 42803 | M20: 0
A21: 5J9CMGDV | B21: Elease Gluck | C21: {=_xlfn.XLOOKUP($B21, sales_teams!$A$2:$A$36, sales_teams!$B$2:$B$36)} -> Celia Rouche | D21: {=_xlfn.XLOOKUP($B21, sales_teams!$A$2:$A$36, sales_teams!$C$2:$C$36)} -> West | E21: MG Special | F21: Rantouch | G21: {=IF($F21="", "", _xlfn.XLOOKUP($F21,accounts!$A$2:$A$86,accounts!$B$2:$B$86, "Other"))} -> telecommunications | H21: {=IF($F21="", "", IFS(_xlfn.XLOOKUP($F21, accounts!$A$2:$A$86, accounts!$E$2:$E$86, 0)>=1000, "Enterprise", _xlfn.XLOOKUP($F21, accounts!$A$2:$A$86, accounts!$E$2:$E$86, 0)>=100, "Mid-Market", TRUE, "SMB"))} -> Enterprise | I21: {=IF($F21="", "", _xlfn.XLOOKUP($F21,accounts!$A$2:$A$86,accounts!$F$2:$F$86, "Other"))} -> United States | J21: Won | K21: 42681 | L21: 42802 | M21: 46
A22: JJXRR8R6 | B22: James Ascencio | C22: {=_xlfn.XLOOKUP($B22, sales_teams!$A$2:$A$36, sales_teams!$B$2:$B$36)} -> Summer Sewald | D22: {=_xlfn.XLOOKUP($B22, sales_teams!$A$2:$A$36, sales_teams!$C$2:$C$36)} -> West | E22: GTX Plus Pro | F22: Fasehatice | G22: {=IF($F22="", "", _xlfn.XLOOKUP($F22,accounts!$A$2:$A$86,accounts!$B$2:$B$86, "Other"))} -> retail | H22: {=IF($F22="", "", IFS(_xlfn.XLOOKUP($F22, accounts!$A$2:$A$86, accounts!$E$2:$E$86, 0)>=1000, "Enterprise", _xlfn.XLOOKUP($F22, accounts!$A$2:$A$86, accounts!$E$2:$E$86, 0)>=100, "Mid-Market", TRUE, "SMB"))} -> Enterprise | I22: {=IF($F22="", "", _xlfn.XLOOKUP($F22,accounts!$A$2:$A$86,accounts!$F$2:$F$86, "Other"))} -> United States | J22: Lost | K22: 42681 | L22: 42811 | M22: 0
A23: WF4HA5NW | B23: Moses Frase | C23: {=_xlfn.XLOOKUP($B23, sales_teams!$A$2:$A$36, sales_teams!$B$2:$B$36)} -> Dustin Brinkmann | D23: {=_xlfn.XLOOKUP($B23, sales_teams!$A$2:$A$36, sales_teams!$C$2:$C$36)} -> Central | E23: MG Special | F23: Ron-tech | G23: {=IF($F23="", "", _xlfn.XLOOKUP($F23,accounts!$A$2:$A$86,accounts!$B$2:$B$86, "Other"))} -> medical | H23: {=IF($F23="", "", IFS(_xlfn.XLOOKUP($F23, accounts!$A$2:$A$86, accounts!$E$2:$E$86, 0)>=1000, "Enterprise", _xlfn.XLOOKUP($F23, accounts!$A$2:$A$86, accounts!$E$2:$E$86, 0)>=100, "Mid-Market", TRUE, "SMB"))} -> Enterprise | I23: {=IF($F23="", "", _xlfn.XLOOKUP($F23,accounts!$A$2:$A$86,accounts!$F$2:$F$86, "Other"))} -> United States | J23: Won | K23: 42681 | L23: 42812 | M23: 50
... A26: SBCR987L | B26: Kami Bicknell | C26: {=_xlfn.XLOOKUP($B26, sales_teams!$A$2:$A$36, sales_teams!$B$2:$B$36)} -> Summer Sewald | D26: {=_xlfn.XLOOKUP($B26, sales_teams!$A$2:$A$36, sales_teams!$C$2:$C$36)} -> West | E26: GTX Basic | F26: Zoomit | G26: {=IF($F26="", "", _xlfn.XLOOKUP($F26,accounts!$A$2:$A$86,accounts!$B$2:$B$86, "Other"))} -> entertainment | H26: {=IF($F26="", "", IFS(_xlfn.XLOOKUP($F26, accounts!$A$2:$A$86, accounts!$E$2:$E$86, 0)>=1000, "Enterprise", _xlfn.XLOOKUP($F26, accounts!$A$2:$A$86, accounts!$E$2:$E$86, 0)>=100, "Mid-Market", TRUE, "SMB"))} -> Mid-Market | I26: {=IF($F26="", "", _xlfn.XLOOKUP($F26,accounts!$A$2:$A$86,accounts!$F$2:$F$86, "Other"))} -> United States | J26: Won | K26: 42684 | L26: 42817 | M26: 590
A27: UP409DSB | B27: Maureen Marcano | C27: {=_xlfn.XLOOKUP($B27, sales_teams!$A$2:$A$36, sales_teams!$B$2:$B$36)} -> Summer Sewald | D27: {=_xlfn.XLOOKUP($B27, sales_teams!$A$2:$A$36, sales_teams!$C$2:$C$36)} -> West | E27: MG Advanced | F27: Ganjaflex | G27: {=IF($F27="", "", _xlfn.XLOOKUP($F27,accounts!$A$2:$A$86,accounts!$B$2:$B$86, "Other"))} -> retail | H27: {=IF($F27="", "", IFS(_xlfn.XLOOKUP($F27, accounts!$A$2:$A$86, accounts!$E$2:$E$86, 0)>=1000, "Enterprise", _xlfn.XLOOKUP($F27, accounts!$A$2:$A$86, accounts!$E$2:$E$86, 0)>=100, "Mid-Market", TRUE, "SMB"))} -> Enterprise | I27: {=IF($F27="", "", _xlfn.XLOOKUP($F27,accounts!$A$2:$A$86,accounts!$F$2:$F$86, "Other"))} -> Japan | J27: Engaging | K27: 42684
A28: JSD4APT2 | B28: Versie Hillebrand | C28: {=_xlfn.XLOOKUP($B28, sales_teams!$A$2:$A$36, sales_teams!$B$2:$B$36)} -> Dustin Brinkmann | D28: {=_xlfn.XLOOKUP($B28, sales_teams!$A$2:$A$36, sales_teams!$C$2:$C$36)} -> Central | E28: MG Special | F28: Bioholding | G28: {=IF($F28="", "", _xlfn.XLOOKUP($F28,accounts!$A$2:$A$86,accounts!$B$2:$B$86, "Other"))} -> medical | H28: {=IF($F28="", "", IFS(_xlfn.XLOOKUP($F28, accounts!$A$2:$A$86, accounts!$E$2:$E$86, 0)>=1000, "Enterprise", _xlfn.XLOOKUP($F28, accounts!$A$2:$A$86, accounts!$E$2:$E$86, 0)>=100, "Mid-Market", TRUE, "SMB"))} -> Enterprise | I28: {=IF($F28="", "", _xlfn.XLOOKUP($F28,accounts!$A$2:$A$86,accounts!$F$2:$F$86, "Other"))} -> Philipines | J28: Won | K28: 42684 | L28: 42806 | M28: 61
A29: AO9Z2D17 | B29: Violet Mclelland | C29: {=_xlfn.XLOOKUP($B29, sales_teams!$A$2:$A$36, sales_teams!$B$2:$B$36)} -> Cara Losch | D29: {=_xlfn.XLOOKUP($B29, sales_teams!$A$2:$A$36, sales_teams!$C$2:$C$36)} -> East | E29: GTX Plus Pro | F29: Xx-zobam | G29: {=IF($F29="", "", _xlfn.XLOOKUP($F29,accounts!$A$2:$A$86,accounts!$B$2:$B$86, "Other"))} -> entertainment | H29: {=IF($F29="", "", IFS(_xlfn.XLOOKUP($F29, accounts!$A$2:$A$86, accounts!$E$2:$E$86, 0)>=1000, "Enterprise", _xlfn.XLOOKUP($F29, accounts!$A$2:$A$86, accounts!$E$2:$E$86, 0)>=100, "Mid-Market", TRUE, "SMB"))} -> Enterprise | I29: {=IF($F29="", "", _xlfn.XLOOKUP($F29,accounts!$A$2:$A$86,accounts!$F$2:$F$86, "Other"))} -> United States | J29: Lost | K29: 42684 | L29: 42805 | M29: 0
A30: 5M58DTJK | B30: Elease Gluck | C30: {=_xlfn.XLOOKUP($B30, sales_teams!$A$2:$A$36, sales_teams!$B$2:$B$36)} -> Celia Rouche | D30: {=_xlfn.XLOOKUP($B30, sales_teams!$A$2:$A$36, sales_teams!$C$2:$C$36)} -> West | E30: MG Special | F30: Cheers | G30: {=IF($F30="", "", _xlfn.XLOOKUP($F30,accounts!$A$2:$A$86,accounts!$B$2:$B$86, "Other"))} -> entertainment | H30: {=IF($F30="", "", IFS(_xlfn.XLOOKUP($F30, accounts!$A$2:$A$86, accounts!$E$2:$E$86, 0)>=1000, "Enterprise", _xlfn.XLOOKUP($F30, accounts!$A$2:$A$86, accounts!$E$2:$E$86, 0)>=100, "Mid-Market", TRUE, "SMB"))} -> Enterprise | I30: {=IF($F30="", "", _xlfn.XLOOKUP($F30,accounts!$A$2:$A$86,accounts!$F$2:$F$86, "Other"))} -> United States | J30: Won | K30: 42685 | L30: 42799 | M30: 58
A31: KNY1OSAB | B31: Maureen Marcano | C31: {=_xlfn.XLOOKUP($B31, sales_teams!$A$2:$A$36, sales_teams!$B$2:$B$36)} -> Summer Sewald | D31: {=_xlfn.XLOOKUP($B31, sales_teams!$A$2:$A$36, sales_teams!$C$2:$C$36)} -> West | E31: GTXPro | F31: Labdrill | G31: {=IF($F31="", "", _xlfn.XLOOKUP($F31,accounts!$A$2:$A$86,accounts!$B$2:$B$86, "Other"))} -> medical | H31: {=IF($F31="", "", IFS(_xlfn.XLOOKUP($F31, accounts!$A$2:$A$86, accounts!$E$2:$E$86, 0)>=1000, "Enterprise", _xlfn.XLOOKUP($F31, accounts!$A$2:$A$86, accounts!$E$2:$E$86, 0)>=100, "Mid-Market", TRUE, "SMB"))} -> Enterprise | I31: {=IF($F31="", "", _xlfn.XLOOKUP($F31,accounts!$A$2:$A$86,accounts!$F$2:$F$86, "Other"))} -> United States | J31: Won | K31: 42685 | L31: 42808 | M31: 4899
A32: EAZDUUM9 | B32: Rosie Papadopoulos | C32: {=_xlfn.XLOOKUP($B32, sales_teams!$A$2:$A$36, sales_teams!$B$2:$B$36)} -> Cara Losch | D32: {=_xlfn.XLOOKUP($B32, sales_teams!$A$2:$A$36, sales_teams!$C$2:$C$36)} -> East | E32: MG Advanced | F32: Zotware | G32: {=IF($F32="", "", _xlfn.XLOOKUP($F32,accounts!$A$2:$A$86,accounts!$B$2:$B$86, "Other"))} -> software | H32: {=IF($F32="", "", IFS(_xlfn.XLOOKUP($F32, accounts!$A$2:$A$86, accounts!$E$2:$E$86, 0)>=1000, "Enterprise", _xlfn.XLOOKUP($F32, accounts!$A$2:$A$86, accounts!$E$2:$E$86, 0)>=100, "Mid-Market", TRUE, "SMB"))} -> Enterprise | I32: {=IF($F32="", "", _xlfn.XLOOKUP($F32,accounts!$A$2:$A$86,accounts!$F$2:$F$86, "Other"))} -> United States | J32: Lost | K32: 42685 | L32: 42795 | M32: 0
A33: 2STUSOFE | B33: Versie Hillebrand | C33: {=_xlfn.XLOOKUP($B33, sales_teams!$A$2:$A$36, sales_teams!$B$2:$B$36)} -> Dustin Brinkmann | D33: {=_xlfn.XLOOKUP($B33, sales_teams!$A$2:$A$36, sales_teams!$C$2:$C$36)} -> Central | E33: MG Special | F33: dambase | G33: {=IF($F33="", "", _xlfn.XLOOKUP($F33,accounts!$A$2:$A$86,accounts!$B$2:$B$86, "Other"))} -> marketing | H33: {=IF($F33="", "", IFS(_xlfn.XLOOKUP($F33, accounts!$A$2:$A$86, accounts!$E$2:$E$86, 0)>=1000, "Enterprise", _xlfn.XLOOKUP($F33, accounts!$A$2:$A$86, accounts!$E$2:$E$86, 0)>=100, "Mid-Market", TRUE, "SMB"))} -> Enterprise | I33: {=IF($F33="", "", _xlfn.XLOOKUP($F33,accounts!$A$2:$A$86,accounts!$F$2:$F$86, "Other"))} -> United States | J33: Won | K33: 42685 | L33: 42797 | M33: 67
A34: JYKM0B00 | B34: James Ascencio | C34: {=_xlfn.XLOOKUP($B34, sales_teams!$A$2:$A$36, sales_teams!$B$2:$B$36)} -> Summer Sewald | D34: {=_xlfn.XLOOKUP($B34, sales_teams!$A$2:$A$36, sales_teams!$C$2:$C$36)} -> West | E34: GTXPro | F34: Xx-holding | G34: {=IF($F34="", "", _xlfn.XLOOKUP($F34,accounts!$A$2:$A$86,accounts!$B$2:$B$86, "Other"))} -> finance | H34: {=IF($F34="", "", IFS(_xlfn.XLOOKUP($F34, accounts!$A$2:$A$86, accounts!$E$2:$E$86, 0)>=1000, "Enterprise", _xlfn.XLOOKUP($F34, accounts!$A$2:$A$86, accounts!$E$2:$E$86, 0)>=100, "Mid-Market", TRUE, "SMB"))} -> Enterprise | I34: {=IF($F34="", "", _xlfn.XLOOKUP($F34,accounts!$A$2:$A$86,accounts!$F$2:$F$86, "Other"))} -> United States | J34: Won | K34: 42686 | L34: 42800 | M34: 4338
A35: KU28360J | B35: Kary Hendrixson | C35: {=_xlfn.XLOOKUP($B35, sales_teams!$A$2:$A$36, sales_teams!$B$2:$B$36)} -> Summer Sewald | D35: {=_xlfn.XLOOKUP($B35, sales_teams!$A$2:$A$36, sales_teams!$C$2:$C$36)} -> West | E35: GTX Basic | F35: Fasehatice | G35: {=IF($F35="", "", _xlfn.XLOOKUP($F35,accounts!$A$2:$A$86,accounts!$B$2:$B$86, "Other"))} -> retail | H35: {=IF($F35="", "", IFS(_xlfn.XLOOKUP($F35, accounts!$A$2:$A$86, accounts!$E$2:$E$86, 0)>=1000, "Enterprise", _xlfn.XLOOKUP($F35, accounts!$A$2:$A$86, accounts!$E$2:$E$86, 0)>=100, "Mid-Market", TRUE, "SMB"))} -> Enterprise | I35: {=IF($F35="", "", _xlfn.XLOOKUP($F35,accounts!$A$2:$A$86,accounts!$F$2:$F$86, "Other"))} -> United States | J35: Won | K35: 42686 | L35: 42813 | M35: 578
A36: N4SD17JR | B36: Reed Clapper | C36: {=_xlfn.XLOOKUP($B36, sales_teams!$A$2:$A$36, sales_teams!$B$2:$B$36)} -> Rocco Neubert | D36: {=_xlfn.XLOOKUP($B36, sales_teams!$A$2:$A$36, sales_teams!$C$2:$C$36)} -> East | E36: GTX Basic | F36: Acme Corporation | G36: {=IF($F36="", "", _xlfn.XLOOKUP($F36,accounts!$A$2:$A$86,accounts!$B$2:$B$86, "Other"))} -> technology | H36: {=IF($F36="", "", IFS(_xlfn.XLOOKUP($F36, accounts!$A$2:$A$86, accounts!$E$2:$E$86, 0)>=1000, "Enterprise", _xlfn.XLOOKUP($F36, accounts!$A$2:$A$86, accounts!$E$2:$E$86, 0)>=100, "Mid-Market", TRUE, "SMB"))} -> Enterprise | I36: {=IF($F36="", "", _xlfn.XLOOKUP($F36,accounts!$A$2:$A$86,accounts!$F$2:$F$86, "Other"))} -> United States | J36: Won | K36: 42686 | L36: 42795 | M36: 556
A37: E67P9Y3Q | B37: Rosalina Dieter | C37: {=_xlfn.XLOOKUP($B37, sales_teams!$A$2:$A$36, sales_teams!$B$2:$B$36)} -> Celia Rouche | D37: {=_xlfn.XLOOKUP($B37, sales_teams!$A$2:$A$36, sales_teams!$C$2:$C$36)} -> West | E37: GTX Basic | F37: Green-Plus | G37: {=IF($F37="", "", _xlfn.XLOOKUP($F37,accounts!$A$2:$A$86,accounts!$B$2:$B$86, "Other"))} -> services | H37: {=IF($F37="", "", IFS(_xlfn.XLOOKUP($F37, accounts!$A$2:$A$86, accounts!$E$2:$E$86, 0)>=1000, "Enterprise", _xlfn.XLOOKUP($F37, accounts!$A$2:$A$86, accounts!$E$2:$E$86, 0)>=100, "Mid-Market", TRUE, "SMB"))} -> Enterprise | I37: {=IF($F37="", "", _xlfn.XLOOKUP($F37,accounts!$A$2:$A$86,accounts!$F$2:$F$86, "Other"))} -> United States | J37: Won | K37: 42686 | L37: 42797 | M37: 635
A38: AT3MMVIS | B38: Wilburn Farren | C38: {=_xlfn.XLOOKUP($B38, sales_teams!$A$2:$A$36, sales_teams!$B$2:$B$36)} -> Cara Losch | D38: {=_xlfn.XLOOKUP($B38, sales_teams!$A$2:$A$36, sales_teams!$C$2:$C$36)} -> East | E38: MG Advanced | F38: The New York Inquirer | G38: {=IF($F38="", "", _xlfn.XLOOKUP($F38,accounts!$A$2:$A$86,accounts!$B$2:$B$86, "Other"))} -> medical | H38: {=IF($F38="", "", IFS(_xlfn.XLOOKUP($F38, accounts!$A$2:$A$86, accounts!$E$2:$E$86, 0)>=1000, "Enterprise", _xlfn.XLOOKUP($F38, accounts!$A$2:$A$86, accounts!$E$2:$E$86, 0)>=100, "Mid-Market", TRUE, "SMB"))} -> Mid-Market | I38: {=IF($F38="", "", _xlfn.XLOOKUP($F38,accounts!$A$2:$A$86,accounts!$F$2:$F$86, "Other"))} -> United States | J38: Won | K38: 42686 | L38: 42801 | M38: 3045
A39: REJ11LRY | B39: Garret Kinder | C39: {=_xlfn.XLOOKUP($B39, sales_teams!$A$2:$A$36, sales_teams!$B$2:$B$36)} -> Cara Losch | D39: {=_xlfn.XLOOKUP($B39, sales_teams!$A$2:$A$36, sales_teams!$C$2:$C$36)} -> East | E39: GTX Plus Basic | F39: Mathtouch | G39: {=IF($F39="", "", _xlfn.XLOOKUP($F39,accounts!$A$2:$A$86,accounts!$B$2:$B$86, "Other"))} -> marketing | H39: {=IF($F39="", "", IFS(_xlfn.XLOOKUP($F39, accounts!$A$2:$A$86, accounts!$E$2:$E$86, 0)>=1000, "Enterprise", _xlfn.XLOOKUP($F39, accounts!$A$2:$A$86, accounts!$E$2:$E$86, 0)>=100, "Mid-Market", TRUE, "SMB"))} -> Enterprise | I39: {=IF($F39="", "", _xlfn.XLOOKUP($F39,accounts!$A$2:$A$86,accounts!$F$2:$F$86, "Other"))} -> Jordan | J39: Won | K39: 42687 | L39: 42808 | M39: 1233
... A43: CZVN09WN | B43: Darcel Schlecht | C43: {=_xlfn.XLOOKUP($B43, sales_teams!$A$2:$A$36, sales_teams!$B$2:$B$36)} -> Melvin Marxen | D43: {=_xlfn.XLOOKUP($B43, sales_teams!$A$2:$A$36, sales_teams!$C$2:$C$36)} -> Central | E43: GTX Plus Basic | F43: Konmatfix | G43: {=IF($F43="", "", _xlfn.XLOOKUP($F43,accounts!$A$2:$A$86,accounts!$B$2:$B$86, "Other"))} -> marketing | H43: {=IF($F43="", "", IFS(_xlfn.XLOOKUP($F43, accounts!$A$2:$A$86, accounts!$E$2:$E$86, 0)>=1000, "Enterprise", _xlfn.XLOOKUP($F43, accounts!$A$2:$A$86, accounts!$E$2:$E$86, 0)>=100, "Mid-Market", TRUE, "SMB"))} -> Enterprise | I43: {=IF($F43="", "", _xlfn.XLOOKUP($F43,accounts!$A$2:$A$86,accounts!$F$2:$F$86, "Other"))} -> United States | J43: Won | K43: 42688 | L43: 42814 | M43: 1170
A44: EG7OFLFR | B44: Kami Bicknell | C44: {=_xlfn.XLOOKUP($B44, sales_teams!$A$2:$A$36, sales_teams!$B$2:$B$36)} -> Summer Sewald | D44: {=_xlfn.XLOOKUP($B44, sales_teams!$A$2:$A$36, sales_teams!$C$2:$C$36)} -> West | E44: GTX Basic | G44: {=IF($F44="", "", _xlfn.XLOOKUP($F44,accounts!$A$2:$A$86,accounts!$B$2:$B$86, "Other"))} | H44: {=IF($F44="", "", IFS(_xlfn.XLOOKUP($F44, accounts!$A$2:$A$86, accounts!$E$2:$E$86, 0)>=1000, "Enterprise", _xlfn.XLOOKUP($F44, accounts!$A$2:$A$86, accounts!$E$2:$E$86, 0)>=100, "Mid-Market", TRUE, "SMB"))} | I44: {=IF($F44="", "", _xlfn.XLOOKUP($F44,accounts!$A$2:$A$86,accounts!$F$2:$F$86, "Other"))} | J44: Engaging | K44: 42688
A45: 30UQWUKB | B45: Marty Freudenburg | C45: {=_xlfn.XLOOKUP($B45, sales_teams!$A$2:$A$36, sales_teams!$B$2:$B$36)} -> Melvin Marxen | D45: {=_xlfn.XLOOKUP($B45, sales_teams!$A$2:$A$36, sales_teams!$C$2:$C$36)} -> Central | E45: GTX Plus Basic | F45: Genco Pura Olive Oil Company | G45: {=IF($F45="", "", _xlfn.XLOOKUP($F45,accounts!$A$2:$A$86,accounts!$B$2:$B$86, "Other"))} -> retail | H45: {=IF($F45="", "", IFS(_xlfn.XLOOKUP($F45, accounts!$A$2:$A$86, accounts!$E$2:$E$86, 0)>=1000, "Enterprise", _xlfn.XLOOKUP($F45, accounts!$A$2:$A$86, accounts!$E$2:$E$86, 0)>=100, "Mid-Market", TRUE, "SMB"))} -> Enterprise | I45: {=IF($F45="", "", _xlfn.XLOOKUP($F45,accounts!$A$2:$A$86,accounts!$F$2:$F$86, "Other"))} -> Italy | J45: Won | K45: 42689 | L45: 42814 | M45: 1162
...

Sheet sales_teams
A1: sales_agent | B1: manager | C1: regional_office
A2: Anna Snelling | B2: Dustin Brinkmann | C2: Central
A3: Cecily Lampkin | B3: Dustin Brinkmann | C3: Central
A4: Versie Hillebrand | B4: Dustin Brinkmann | C4: Central
A5: Lajuana Vencill | B5: Dustin Brinkmann | C5: Central
A6: Moses Frase | B6: Dustin Brinkmann | C6: Central
A7: Jonathan Berthelot | B7: Melvin Marxen | C7: Central
A8: Marty Freudenburg | B8: Melvin Marxen | C8: Central
A9: Gladys Colclough | B9: Melvin Marxen | C9: Central
A10: Niesha Huffines | B10: Melvin Marxen | C10: Central
A11: Darcel Schlecht | B11: Melvin Marxen | C11: Central
A12: Mei-Mei Johns | B12: Melvin Marxen | C12: Central
... A36: Carl Lin | B36: Summer Sewald | C36: West

Sheet accounts
A1: account | B1: sector | C1: year_established | D1: revenue | E1: employees | F1: office_location | G1: subsidiary_of
A2: Acme Corporation | B2: technology | C2: 1996 | D2: 1100.04 | E2: 2822 | F2: United States
A3: Betasoloin | B3: medical | C3: 1999 | D3: 251.41 | E3: 495 | F3: United States
A4: Betatech | B4: medical | C4: 1986 | D4: 647.18 | E4: 1185 | F4: Kenya
A5: Bioholding | B5: medical | C5: 2012 | D5: 587.34 | E5: 1356 | F5: Philipines
A6: Bioplex | B6: medical | C6: 1991 | D6: 326.82 | E6: 1016 | F6: United States
A7: Blackzim | B7: retail | C7: 2009 | D7: 497.11 | E7: 1588 | F7: United States
A8: Bluth Company | B8: technology | C8: 1993 | D8: 1242.32 | E8: 3027 | F8: United States | G8: Acme Corporation
A9: Bubba Gump | B9: software | C9: 2002 | D9: 987.39 | E9: 2253 | F9: United States
A10: Cancity | B10: retail | C10: 2001 | D10: 718.62 | E10: 2448 | F10: United States
A11: Cheers | B11: entertainment | C11: 1993 | D11: 4269.9 | E11: 6472 | F11: United States | G11: Massive Dynamic
A12: Codehow | B12: software | C12: 1998 | D12: 2714.9 | E12: 2641 | F12: United States | G12: Acme Corporation
A13: Condax | B13: medical | C13: 2017 | D13: 4.54 | E13: 9 | F13: United States
A14: Conecom | B14: technology | C14: 2005 | D14: 1520.66 | E14: 1806 | F14: United States
A15: Dalttechnology | B15: software | C15: 2013 | D15: 98.79 | E15: 96 | F15: United States | G15: Bubba Gump
A16: dambase | B16: marketing | C16: 1995 | D16: 2173.98 | E16: 2928 | F16: United States | G16: Inity
A17: Domzoom | B17: entertainment | C17: 1998 | D17: 217.87 | E17: 551 | F17: United States
A18: Doncon | B18: technology | C18: 2010 | D18: 587.72 | E18: 1501 | F18: United States
A19: Donquadtech | B19: technology | C19: 1992 | D19: 1712.68 | E19: 3194 | F19: United States | G19: Acme Corporation
A20: Dontechi | B20: software | C20: 1982 | D20: 4618 | E20: 10083 | F20: United States
A21: Donware | B21: marketing | C21: 1999 | D21: 1197.44 | E21: 2570 | F21: United States
A22: Fasehatice | B22: retail | C22: 1990 | D22: 4968.91 | E22: 7523 | F22: United States
A23: Faxquote | B23: telecommunications | C23: 1995 | D23: 1825.82 | E23: 5595 | F23: United States | G23: Sonron
A24: Finhigh | B24: finance | C24: 2006 | D24: 1102.43 | E24: 1759 | F24: United States
A25: Finjob | B25: employment | C25: 1988 | D25: 2059.9 | E25: 3644 | F25: United States
A26: Funholding | B26: finance | C26: 1991 | D26: 2819.5 | E26: 7227 | F26: United States | G26: Golddex
A27: Ganjaflex | B27: retail | C27: 1995 | D27: 5158.71 | E27: 17479 | F27: Japan
A28: Gekko & Co | B28: retail | C28: 1990 | D28: 2520.83 | E28: 3502 | F28: United States
A29: Genco Pura Olive Oil Company | B29: retail | C29: 2007 | D29: 894.33 | E29: 1635 | F29: Italy
A30: Globex Corporation | B30: technology | C30: 2000 | D30: 1223.72 | E30: 2497 | F30: Norway
A31: Gogozoom | B31: telecommunications | C31: 2007 | D31: 86.68 | E31: 187 | F31: United States | G31: Sonron
A32: Golddex | B32: finance | C32: 2008 | D32: 52.5 | E32: 165 | F32: United States
A33: Goodsilron | B33: marketing | C33: 2000 | D33: 2952.73 | E33: 5107 | F33: United States
A34: Green-Plus | B34: services | C34: 2003 | D34: 692.19 | E34: 1922 | F34: United States
A35: Groovestreet | B35: retail | C35: 2003 | D35: 223.8 | E35: 299 | F35: United States
A36: Hatfan | B36: services | C36: 1982 | D36: 792.46 | E36: 1299 | F36: United States
A37: Hottechi | B37: technology | C37: 1997 | D37: 8170.38 | E37: 16499 | F37: Korea
A38: Initech | B38: telecommunications | C38: 1994 | D38: 6395.05 | E38: 20275 | F38: United States
A39: Inity | B39: marketing | C39: 1986 | D39: 2403.58 | E39: 8801 | F39: United States
A40: Isdom | B40: medical | C40: 2002 | D40: 3178.24 | E40: 4540 | F40: United States
...

Sheet Bảng tổng hợp 1
B1: close_date - Năm-quý
B2: 2017-Q4 | C2: 2017-Q3 | D2: 2017-Q2 | E2: 2017-Q1 | F2: Tổng cộng
A3: COUNTA của opportunity_id | B3: 1196 | C3: 1257 | D3: 1254 | E3: 531 | F3: 4238
A10: #REF!

Sheet Bảng tổng hợp 2
H1: Revenue and Close Rate by Industry
H2: account_sector | I2: Total of Won | J2: Total value | K2: Close Rate | L2: Avg Deal
H3: employment | I3: =IF(OR($N$12="Tất cả", $N$12=H3), COUNTIFS(sales_pipeline!$G$2:$G1000, H3, sales_pipeline!$H$2:$H1000, IF($R$12="Tất cả", "*", $R$12), sales_pipeline!$J$2:$J1000, "Won"), 0) -> 179 | J3: =IF(OR($N$12="Tất cả", $N$12=H3), SUMIFS(sales_pipeline!$M$2:$M1000, sales_pipeline!$G$2:$G1000, H3, sales_pipeline!$H$2:$H1000, IF($R$12="Tất cả", "*", $R$12), sales_pipeline!$J$2:$J1000, "Won"), 0) -> 436174 | K3: =IF(OR($N$12="Tất cả", $N$12=H3), IFERROR(I3 / COUNTIFS(sales_pipeline!$G$2:$G1000, H3, sales_pipeline!$H$2:$H1000, IF($R$12="Tất cả", "*", $R$12)), 0), 0) -> 0.5755627 | L3: =IFERROR(J3 / I3, 0) -> 2436.7263
H4: entertainment | I4: =IF(OR($N$12="Tất cả", $N$12=H4), COUNTIFS(sales_pipeline!$G$2:$G1000, H4, sales_pipeline!$H$2:$H1000, IF($R$12="Tất cả", "*", $R$12), sales_pipeline!$J$2:$J1000, "Won"), 0) -> 260 | J4: =IF(OR($N$12="Tất cả", $N$12=H4), SUMIFS(sales_pipeline!$M$2:$M1000, sales_pipeline!$G$2:$G1000, H4, sales_pipeline!$H$2:$H1000, IF($R$12="Tất cả", "*", $R$12), sales_pipeline!$J$2:$J1000, "Won"), 0) -> 689007 | K4: =IF(OR($N$12="Tất cả", $N$12=H4), IFERROR(I4 / COUNTIFS(sales_pipeline!$G$2:$G1000, H4, sales_pipeline!$H$2:$H1000, IF($R$12="Tất cả", "*", $R$12)), 0), 0) -> 0.57649667 | L4: =IFERROR(J4 / I4, 0) -> 2650.0269
H5: finance | I5: =IF(OR($N$12="Tất cả", $N$12=H5), COUNTIFS(sales_pipeline!$G$2:$G1000, H5, sales_pipeline!$H$2:$H1000, IF($R$12="Tất cả", "*", $R$12), sales_pipeline!$J$2:$J1000, "Won"), 0) -> 375 | J5: =IF(OR($N$12="Tất cả", $N$12=H5), SUMIFS(sales_pipeline!$M$2:$M1000, sales_pipeline!$G$2:$G1000, H5, sales_pipeline!$H$2:$H1000, IF($R$12="Tất cả", "*", $R$12), sales_pipeline!$J$2:$J1000, "Won"), 0) -> 950908 | K5: =IF(OR($N$12="Tất cả", $N$12=H5), IFERROR(I5 / COUNTIFS(sales_pipeline!$G$2:$G1000, H5, sales_pipeline!$H$2:$H1000, IF($R$12="Tất cả", "*", $R$12)), 0), 0) -> 0.55309735 | L5: =IFERROR(J5 / I5, 0) -> 2535.7547
H6: marketing | I6: =IF(OR($N$12="Tất cả", $N$12=H6), COUNTIFS(sales_pipeline!$G$2:$G1000, H6, sales_pipeline!$H$2:$H1000, IF($R$12="Tất cả", "*", $R$12), sales_pipeline!$J$2:$J1000, "Won"), 0) -> 404 | J6: =IF(OR($N$12="Tất cả", $N$12=H6), SUMIFS(sales_pipeline!$M$2:$M1000, sales_pipeline!$G$2:$G1000, H6, sales_pipeline!$H$2:$H1000, IF($R$12="Tất cả", "*", $R$12), sales_pipeline!$J$2:$J1000, "Won"), 0) -> 922321 | K6: =IF(OR($N$12="Tất cả", $N$12=H6), IFERROR(I6 / COUNTIFS(sales_pipeline!$G$2:$G1000, H6, sales_pipeline!$H$2:$H1000, IF($R$12="Tất cả", "*", $R$12)), 0), 0) -> 0.59940653 | L6: =IFERROR(J6 / I6, 0) -> 2282.9728
H7: medical | I7: =IF(OR($N$12="Tất cả", $N$12=H7), COUNTIFS(sales_pipeline!$G$2:$G1000, H7, sales_pipeline!$H$2:$H1000, IF($R$12="Tất cả", "*", $R$12), sales_pipeline!$J$2:$J1000, "Won"), 0) -> 592 | J7: =IF(OR($N$12="Tất cả", $N$12=H7), SUMIFS(sales_pipeline!$M$2:$M1000, sales_pipeline!$G$2:$G1000, H7, sales_pipeline!$H$2:$H1000, IF($R$12="Tất cả", "*", $R$12), sales_pipeline!$J$2:$J1000, "Won"), 0) -> 1359595 | K7: =IF(OR($N$12="Tất cả", $N$12=H7), IFERROR(I7 / COUNTIFS(sales_pipeline!$G$2:$G1000, H7, sales_pipeline!$H$2:$H1000, IF($R$12="Tất cả", "*", $R$12)), 0), 0) -> 0.56327307 | L7: =IFERROR(J7 / I7, 0) -> 2296.6132
H8: retail | I8: =IF(OR($N$12="Tất cả", $N$12=H8), COUNTIFS(sales_pipeline!$G$2:$G1000, H8, sales_pipeline!$H$2:$H1000, IF($R$12="Tất cả", "*", $R$12), sales_pipeline!$J$2:$J1000, "Won"), 0) -> 799 | J8: =IF(OR($N$12="Tất cả", $N$12=H8), SUMIFS(sales_pipeline!$M$2:$M1000, sales_pipeline!$G$2:$G1000, H8, sales_pipeline!$H$2:$H1000, IF($R$12="Tất cả", "*", $R$12), sales_pipeline!$J$2:$J1000, "Won"), 0) -> 1867528 | K8: =IF(OR($N$12="Tất cả", $N$12=H8), IFERROR(I8 / COUNTIFS(sales_pipeline!$G$2:$G1000, H8, sales_pipeline!$H$2:$H1000, IF($R$12="Tất cả", "*", $R$12)), 0), 0) -> 0.57193987 | L8: =IFERROR(J8 / I8, 0) -> 2337.3317
H9: services | I9: =IF(OR($N$12="Tất cả", $N$12=H9), COUNTIFS(sales_pipeline!$G$2:$G1000, H9, sales_pipeline!$H$2:$H1000, IF($R$12="Tất cả", "*", $R$12), sales_pipeline!$J$2:$J1000, "Won"), 0) -> 223 | J9: =IF(OR($N$12="Tất cả", $N$12=H9), SUMIFS(sales_pipeline!$M$2:$M1000, sales_pipeline!$G$2:$G1000, H9, sales_pipeline!$H$2:$H1000, IF($R$12="Tất cả", "*", $R$12), sales_pipeline!$J$2:$J1000, "Won"), 0) -> 533006 | K9: =IF(OR($N$12="Tất cả", $N$12=H9), IFERROR(I9 / COUNTIFS(sales_pipeline!$G$2:$G1000, H9, sales_pipeline!$H$2:$H1000, IF($R$12="Tất cả", "*", $R$12)), 0), 0) -> 0.57179487 | L9: =IFERROR(J9 / I9, 0) -> 2390.1614
H10: software | I10: =IF(OR($N$12="Tất cả", $N$12=H10), COUNTIFS(sales_pipeline!$G$2:$G1000, H10, sales_pipeline!$H$2:$H1000, IF($R$12="Tất cả", "*", $R$12), sales_pipeline!$J$2:$J1000, "Won"), 0) -> 450 | J10: =IF(OR($N$12="Tất cả", $N$12=H10), SUMIFS(sales_pipeline!$M$2:$M1000, sales_pipeline!$G$2:$G1000, H10, sales_pipeline!$H$2:$H1000, IF($R$12="Tất cả", "*", $R$12), sales_pipeline!$J$2:$J1000, "Won"), 0) -> 1077934 | K10: =IF(OR($N$12="Tất cả", $N$12=H10), IFERROR(I10 / COUNTIFS(sales_pipeline!$G$2:$G1000, H10, sales_pipeline!$H$2:$H1000, IF($R$12="Tất cả", "*", $R$12)), 0), 0) -> 0.59445178 | L10: =IFERROR(J10 / I10, 0) -> 2395.4089
H11: technology | I11: =IF(OR($N$12="Tất cả", $N$12=H11), COUNTIFS(sales_pipeline!$G$2:$G1000, H11, sales_pipeline!$H$2:$H1000, IF($R$12="Tất cả", "*", $R$12), sales_pipeline!$J$2:$J1000, "Won"), 0) -> 671 | J11: =IF(OR($N$12="Tất cả", $N$12=H11), SUMIFS(sales_pipeline!$M$2:$M1000, sales_pipeline!$G$2:$G1000, H11, sales_pipeline!$H$2:$H1000, IF($R$12="Tất cả", "*", $R$12), sales_pipeline!$J$2:$J1000, "Won"), 0) -> 1515487 | K11: =IF(OR($N$12="Tất cả", $N$12=H11), IFERROR(I11 / COUNTIFS(sales_pipeline!$G$2:$G1000, H11, sales_pipeline!$H$2:$H1000, IF($R$12="Tất cả", "*", $R$12)), 0), 0) -> 0.57596567 | L11: =IFERROR(J11 / I11, 0) -> 2258.5499
H12: telecommunications | I12: =IF(OR($N$12="Tất cả", $N$12=H12), COUNTIFS(sales_pipeline!$G$2:$G1000, H12, sales_pipeline!$H$2:$H1000, IF($R$12="Tất cả", "*", $R$12), sales_pipeline!$J$2:$J1000, "Won"), 0) -> 285 | J12: =IF(OR($N$12="Tất cả", $N$12=H12), SUMIFS(sales_pipeline!$M$2:$M1000, sales_pipeline!$G$2:$G1000, H12, sales_pipeline!$H$2:$H1000, IF($R$12="Tất cả", "*", $R$12), sales_pipeline!$J$2:$J1000, "Won"), 0) -> 653574 | K12: =IF(OR($N$12="Tất cả", $N$12=H12), IFERROR(I12 / COUNTIFS(sales_pipeline!$G$2:$G1000, H12, sales_pipeline!$H$2:$H1000, IF($R$12="Tất cả", "*", $R$12)), 0), 0) -> 0.56886228 | L12: =IFERROR(J12 / I12, 0) -> 2293.2421 | M12: Ngành nghề: | N12: Tất cả | Q12: Quy mô: | R12: Tất cả
H13: Tổng cộng | I13: =SUM(I3:I12) -> 4238 | J13: =SUM(J3:J12) -> 10005534 | K13: =IFERROR(I13 / SUMPRODUCT(COUNTIFS(sales_pipeline!$G$2:$G1000, IF($N$12="Tất cả", H3:H12, $N$12), sales_pipeline!$H$2:$H1000, IF($R$12="Tất cả", "*", $R$12))), 0) -> 0.57464407 | L13: =IFERROR(J13 / I13, 0) -> 2360.9094
H14: {=IFERROR(INDEX(H3:H12, MATCH(MAX(J3:J12), J3:J12, 0)), "N/A")} -> retail | I14: {=IFERROR(INDEX(I3:I12, MATCH(MAX(J3:J12), J3:J12, 0)), 0)} -> 799 | J14: =IFERROR(MAX(J3:J12), 0) -> 1867528
H16: Revenue and Close Rate by Size
H17: size | I17: Total of Won | J17: Total value | K17: Close Rate
H18: SMB | I18: =IF(OR($R$12="Tất cả", $R$12=H18), COUNTIFS(sales_pipeline!$H$2:$H1000, H18, sales_pipeline!$G$2:$G1000, IF($N$12="Tất cả", "*", $N$12), sales_pipeline!$J$2:$J1000, "Won"), 0) -> 148 | J18: =IF(OR($R$12="Tất cả", $R$12=H18), SUMIFS(sales_pipeline!$M$2:$M1000, sales_pipeline!$H$2:$H1000, H18, sales_pipeline!$G$2:$G1000, IF($N$12="Tất cả", "*", $N$12), sales_pipeline!$J$2:$J1000, "Won"), 0) -> 284346 | K18: =IF(OR($R$12="Tất cả", $R$12=H18), IFERROR(I18 / COUNTIFS(sales_pipeline!$H$2:$H1000, H18, sales_pipeline!$G$2:$G1000, IF($N$12="Tất cả", "*", $N$12)), 0), 0) -> 0.61157025
H19: Mid-Market | I19: =IF(OR($R$12="Tất cả", $R$12=H19), COUNTIFS(sales_pipeline!$H$2:$H1000, H19, sales_pipeline!$G$2:$G1000, IF($N$12="Tất cả", "*", $N$12), sales_pipeline!$J$2:$J1000, "Won"), 0) -> 575 | J19: =IF(OR($R$12="Tất cả", $R$12=H19), SUMIFS(sales_pipeline!$M$2:$M1000, sales_pipeline!$H$2:$H1000, H19, sales_pipeline!$G$2:$G1000, IF($N$12="Tất cả", "*", $N$12), sales_pipeline!$J$2:$J1000, "Won"), 0) -> 1309735 | K19: =IF(OR($R$12="Tất cả", $R$12=H19), IFERROR(I19 / COUNTIFS(sales_pipeline!$H$2:$H1000, H19, sales_pipeline!$G$2:$G1000, IF($N$12="Tất cả", "*", $N$12)), 0), 0) -> 0.54971319
H20: Enterprise | I20: =IF(OR($R$12="Tất cả", $R$12=H20), COUNTIFS(sales_pipeline!$H$2:$H1000, H20, sales_pipeline!$G$2:$G1000, IF($N$12="Tất cả", "*", $N$12), sales_pipeline!$J$2:$J1000, "Won"), 0) -> 3515 | J20: =IF(OR($R$12="Tất cả", $R$12=H20), SUMIFS(sales_pipeline!$M$2:$M1000, sales_pipeline!$H$2:$H1000, H20, sales_pipeline!$G$2:$G1000, IF($N$12="Tất cả", "*", $N$12), sales_pipeline!$J$2:$J1000, "Won"), 0) -> 8411453 | K20: =IF(OR($R$12="Tất cả", $R$12=H20), IFERROR(I20 / COUNTIFS(sales_pipeline!$H$2:$H1000, H20, sales_pipeline!$G$2:$G1000, IF($N$12="Tất cả", "*", $N$12)), 0), 0) -> 0.57746016
H21: Tổng cộng | I21: =SUM(I18:I20) -> 4238 | J21: =SUM(J18:J20) -> 10005534 | K21: =IFERROR(I21 / SUMPRODUCT(COUNTIFS(sales_pipeline!$H$2:$H1000, IF($R$12="Tất cả", H18:H20, $R$12), sales_pipeline!$G$2:$G1000, IF($N$12="Tất cả", "*", $N$12))), 0) -> 0.57464407
H23: Revenue by Country
H24: location | I24: Total of Won | J24: Total value
H25: United States | I25: =COUNTIFS(sales_pipeline!$I$2:$I1000, H25, sales_pipeline!$G$2:$G1000, IF($N$12="Tất cả", "*", $N$12), sales_pipeline!$H$2:$H1000, IF($R$12="Tất cả", "*", $R$12), sales_pipeline!$J$2:$J1000, "Won") -> 3514 | J25: =SUMIFS(sales_pipeline!$M$2:$M1000, sales_pipeline!$I$2:$I1000, H25, sales_pipeline!$G$2:$G1000, IF($N$12="Tất cả", "*", $N$12), sales_pipeline!$H$2:$H1000, IF($R$12="Tất cả", "*", $R$12), sales_pipeline!$J$2:$J1000, "Won") -> 8426955
H26: Korea | I26: =COUNTIFS(sales_pipeline!$I$2:$I1000, H26, sales_pipeline!$G$2:$G1000, IF($N$12="Tất cả", "*", $N$12), sales_pipeline!$H$2:$H1000, IF($R$12="Tất cả", "*", $R$12), sales_pipeline!$J$2:$J1000, "Won") -> 111 | J26: =SUMIFS(sales_pipeline!$M$2:$M1000, sales_pipeline!$I$2:$I1000, H26, sales_pipeline!$G$2:$G1000, IF($N$12="Tất cả", "*", $N$12), sales_pipeline!$H$2:$H1000, IF($R$12="Tất cả", "*", $R$12), sales_pipeline!$J$2:$J1000, "Won") -> 194957
H27: Panama | I27: =COUNTIFS(sales_pipeline!$I$2:$I1000, H27, sales_pipeline!$G$2:$G1000, IF($N$12="Tất cả", "*", $N$12), sales_pipeline!$H$2:$H1000, IF($R$12="Tất cả", "*", $R$12), sales_pipeline!$J$2:$J1000, "Won") -> 75 | J27: =SUMIFS(sales_pipeline!$M$2:$M1000, sales_pipeline!$I$2:$I1000, H27, sales_pipeline!$G$2:$G1000, IF($N$12="Tất cả", "*", $N$12), sales_pipeline!$H$2:$H1000, IF($R$12="Tất cả", "*", $R$12), sales_pipeline!$J$2:$J1000, "Won") -> 151777
H28: Belgium | I28: =COUNTIFS(sales_pipeline!$I$2:$I1000, H28, sales_pipeline!$G$2:$G1000, IF($N$12="Tất cả", "*", $N$12), sales_pipeline!$H$2:$H1000, IF($R$12="Tất cả", "*", $R$12), sales_pipeline!$J$2:$J1000, "Won") -> 63 | J28: =SUMIFS(sales_pipeline!$M$2:$M1000, sales_pipeline!$I$2:$I1000, H28, sales_pipeline!$G$2:$G1000, IF($N$12="Tất cả", "*", $N$12), sales_pipeline!$H$2:$H1000, IF($R$12="Tất cả", "*", $R$12), sales_pipeline!$J$2:$J1000, "Won") -> 117463
H29: Philipines | I29: =COUNTIFS(sales_pipeline!$I$2:$I1000, H29, sales_pipeline!$G$2:$G1000, IF($N$12="Tất cả", "*", $N$12), sales_pipeline!$H$2:$H1000, IF($R$12="Tất cả", "*", $R$12), sales_pipeline!$J$2:$J1000, "Won") -> 50 | J29: =SUMIFS(sales_pipeline!$M$2:$M1000, sales_pipeline!$I$2:$I1000, H29, sales_pipeline!$G$2:$G1000, IF($N$12="Tất cả", "*", $N$12), sales_pipeline!$H$2:$H1000, IF($R$12="Tất cả", "*", $R$12), sales_pipeline!$J$2:$J1000, "Won") -> 90991
H30: Italy | I30: =COUNTIFS(sales_pipeline!$I$2:$I1000, H30, sales_pipeline!$G$2:$G1000, IF($N$12="Tất cả", "*", $N$12), sales_pipeline!$H$2:$H1000, IF($R$12="Tất cả", "*", $R$12), sales_pipeline!$J$2:$J1000, "Won") -> 54 | J30: =SUMIFS(sales_pipeline!$M$2:$M1000, sales_pipeline!$I$2:$I1000, H30, sales_pipeline!$G$2:$G1000, IF($N$12="Tất cả", "*", $N$12), sales_pipeline!$H$2:$H1000, IF($R$12="Tất cả", "*", $R$12), sales_pipeline!$J$2:$J1000, "Won") -> 114352
H31: Kenya | I31: =COUNTIFS(sales_pipeline!$I$2:$I1000, H31, sales_pipeline!$G$2:$G1000, IF($N$12="Tất cả", "*", $N$12), sales_pipeline!$H$2:$H1000, IF($R$12="Tất cả", "*", $R$12), sales_pipeline!$J$2:$J1000, "Won") -> 53 | J31: =SUMIFS(sales_pipeline!$M$2:$M1000, sales_pipeline!$I$2:$I1000, H31, sales_pipeline!$G$2:$G1000, IF($N$12="Tất cả", "*", $N$12), sales_pipeline!$H$2:$H1000, IF($R$12="Tất cả", "*", $R$12), sales_pipeline!$J$2:$J1000, "Won") -> 107408
H32: Norway | I32: =COUNTIFS(sales_pipeline!$I$2:$I1000, H32, sales_pipeline!$G$2:$G1000, IF($N$12="Tất cả", "*", $N$12), sales_pipeline!$H$2:$H1000, IF($R$12="Tất cả", "*", $R$12), sales_pipeline!$J$2:$J1000, "Won") -> 50 | J32: =SUMIFS(sales_pipeline!$M$2:$M1000, sales_pipeline!$I$2:$I1000, H32, sales_pipeline!$G$2:$G1000, IF($N$12="Tất cả", "*", $N$12), sales_pipeline!$H$2:$H1000, IF($R$12="Tất cả", "*", $R$12), sales_pipeline!$J$2:$J1000, "Won") -> 115712
H33: Jordan | I33: =COUNTIFS(sales_pipeline!$I$2:$I1000, H33, sales_pipeline!$G$2:$G1000, IF($N$12="Tất cả", "*", $N$12), sales_pipeline!$H$2:$H1000, IF($R$12="Tất cả", "*", $R$12), sales_pipeline!$J$2:$J1000, "Won") -> 52 | J33: =SUMIFS(sales_pipeline!$M$2:$M1000, sales_pipeline!$I$2:$I1000, H33, sales_pipeline!$G$2:$G1000, IF($N$12="Tất cả", "*", $N$12), sales_pipeline!$H$2:$H1000, IF($R$12="Tất cả", "*", $R$12), sales_pipeline!$J$2:$J1000, "Won") -> 163339
H34: Japan | I34: =COUNTIFS(sales_pipeline!$I$2:$I1000, H34, sales_pipeline!$G$2:$G1000, IF($N$12="Tất cả", "*", $N$12), sales_pipeline!$H$2:$H1000, IF($R$12="Tất cả", "*", $R$12), sales_pipeline!$J$2:$J1000, "Won") -> 46 | J34: =SUMIFS(sales_pipeline!$M$2:$M1000, sales_pipeline!$I$2:$I1000, H34, sales_pipeline!$G$2:$G1000, IF($N$12="Tất cả", "*", $N$12), sales_pipeline!$H$2:$H1000, IF($R$12="Tất cả", "*", $R$12), sales_pipeline!$J$2:$J1000, "Won") -> 123506
H35: Poland | I35: =COUNTIFS(sales_pipeline!$I$2:$I1000, H35, sales_pipeline!$G$2:$G1000, IF($N$12="Tất cả", "*", $N$12), sales_pipeline!$H$2:$H1000, IF($R$12="Tất cả", "*", $R$12), sales_pipeline!$J$2:$J1000, "Won") -> 45 | J35: =SUMIFS(sales_pipeline!$M$2:$M1000, sales_pipeline!$I$2:$I1000, H35, sales_pipeline!$G$2:$G1000, IF($N$12="Tất cả", "*", $N$12), sales_pipeline!$H$2:$H1000, IF($R$12="Tất cả", "*", $R$12), sales_pipeline!$J$2:$J1000, "Won") -> 106754
H36: Brazil | I36: =COUNTIFS(sales_pipeline!$I$2:$I1000, H36, sales_pipeline!$G$2:$G1000, IF($N$12="Tất cả", "*", $N$12), sales_pipeline!$H$2:$H1000, IF($R$12="Tất cả", "*", $R$12), sales_pipeline!$J$2:$J1000, "Won") -> 32 | J36: =SUMIFS(sales_pipeline!$M$2:$M1000, sales_pipeline!$I$2:$I1000, H36, sales_pipeline!$G$2:$G1000, IF($N$12="Tất cả", "*", $N$12), sales_pipeline!$H$2:$H1000, IF($R$12="Tất cả", "*", $R$12), sales_pipeline!$J$2:$J1000, "Won") -> 63103
H37: China | I37: =COUNTIFS(sales_pipeline!$I$2:$I1000, H37, sales_pipeline!$G$2:$G1000, IF($N$12="Tất cả", "*", $N$12), sales_pipeline!$H$2:$H1000, IF($R$12="Tất cả", "*", $R$12), sales_pipeline!$J$2:$J1000, "Won") -> 33 | J37: =SUMIFS(sales_pipeline!$M$2:$M1000, sales_pipeline!$I$2:$I1000, H37, sales_pipeline!$G$2:$G1000, IF($N$12="Tất cả", "*", $N$12), sales_pipeline!$H$2:$H1000, IF($R$12="Tất cả", "*", $R$12), sales_pipeline!$J$2:$J1000, "Won") -> 86690
H38: Germany | I38: =COUNTIFS(sales_pipeline!$I$2:$I1000, H38, sales_pipeline!$G$2:$G1000, IF($N$12="Tất cả", "*", $N$12), sales_pipeline!$H$2:$H1000, IF($R$12="Tất cả", "*", $R$12), sales_pipeline!$J$2:$J1000, "Won") -> 37 | J38: =SUMIFS(sales_pipeline!$M$2:$M1000, sales_pipeline!$I$2:$I1000, H38, sales_pipeline!$G$2:$G1000, IF($N$12="Tất cả", "*", $N$12), sales_pipeline!$H$2:$H1000, IF($R$12="Tất cả", "*", $R$12), sales_pipeline!$J$2:$J1000, "Won") -> 82622
H39: Romania | I39: =COUNTIFS(sales_pipeline!$I$2:$I1000, H39, sales_pipeline!$G$2:$G1000, IF($N$12="Tất cả", "*", $N$12), sales_pipeline!$H$2:$H1000, IF($R$12="Tất cả", "*", $R$12), sales_pipeline!$J$2:$J1000, "Won") -> 23 | J39: =SUMIFS(sales_pipeline!$M$2:$M1000, sales_pipeline!$I$2:$I1000, H39, sales_pipeline!$G$2:$G1000, IF($N$12="Tất cả", "*", $N$12), sales_pipeline!$H$2:$H1000, IF($R$12="Tất cả", "*", $R$12), sales_pipeline!$J$2:$J1000, "Won") -> 59905
H40: Tổng cộng | I40: =SUM(I25:I39) -> 4238 | J40: =SUM(J25:J39) -> 10005534
